<!--
  TRON2 Pro (WF_TRON1A) wheel-biped MuJoCo model.
  Adapted from src/WF_TRON1A/xml/robot.xml for mjlab velocity task.
-->
<mujoco model="tron_pro_wheel_biped">
  <compiler angle="radian" meshdir="../assets/" autolimits="true"/>
  <size njmax="500" nconmax="100"/>

  <default>
    <light castshadow="false" diffuse="1 1 1"/>
    <camera fovy="60"/>
    <default class="visual">
      <geom contype="0" conaffinity="0" group="1" type="mesh" rgba="0.9 0.9 0.9 1.0"/>
    </default>
    <joint armature="0.01" damping="0.01"/>
    <geom contype="1" conaffinity="1" condim="3" friction="0.6 0.005 0.0001" rgba="0.5 0.6 0.7 0.0" margin="0.001" group="0"/>
  </default>

  <visual>
    <rgba com="0.502 1.0 0 0.5" contactpoint="1.0 1.0 0.6 0.4" contactforce="0.2 0.98 0.2 0.8"/>
    <scale com="0.2" forcewidth="0.05" contactwidth="0.10" contactheight="0.04"/>
  </visual>

  <asset>
    <mesh name="base_Link" file="base_Link.STL"/>
    <mesh name="abad_L_Link" file="abad_L_Link.STL"/>
    <mesh name="hip_L_Link" file="hip_L_Link.STL"/>
    <mesh name="knee_L_Link" file="knee_L_Link.STL"/>
    <mesh name="wheel_L_Link" file="wheel_L_Link.STL"/>
    <mesh name="abad_R_Link" file="abad_R_Link.STL"/>
    <mesh name="hip_R_Link" file="hip_R_Link.STL"/>
    <mesh name="knee_R_Link" file="knee_R_Link.STL"/>
    <mesh name="wheel_R_Link" file="wheel_R_Link.STL"/>
  </asset>

  <asset>
    <texture type="skybox" builtin="gradient" width="512" height="512" rgb1="1.0 1.0 1.0" rgb2="1.0 1.0 1.0"/>
    <texture name="texplane" type="2d" builtin="checker" rgb1="0.35 0.35 0.35" rgb2="0.55 0.55 0.55" width="512" height="512" mark="cross" markrgb=".8 .8 .8"/>
    <material name="matplane" reflectance="0.0" texture="texplane" texrepeat="1 1" texuniform="true"/>
  </asset>

  <option timestep="0.001"/>

  <worldbody>
    <geom name="floor" rgba="0.5 0.6 0.7 1" pos="0 0 0" size="0 0 0.25" type="plane" material="matplane" condim="3"/>
    <camera name="track" mode="trackcom" pos="0 -2.3 1.6" xyaxes="1 0 0 0 0.707 0.707"/>
    <light directional="true" diffuse=".8 .8 .8" pos="0 0 10" dir="0 0 -10"/>

    <body name="base" pos="0 0 0.85">
      <inertial pos="0.0457123 0.000139854 -0.163809" quat="0.972578 -0.00615364 -0.232461 0.00398682" mass="9.595" diaginertia="0.154712 0.11093 0.0846371"/>
      <joint type="free" limited="false" damping="0.0000" stiffness="0.0000" armature="0"/>
      <site name="imu" pos="0 0 0"/>
      <geom class="visual" rgba="0.79216 0.81961 0.93333 1" mesh="base_Link"/>
      <geom name="base_collision" type="mesh" mesh="base_Link" rgba="0 0 1 0"/>

      <body name="abad_L_Link" pos="0.05556 0.105 -0.2602">
        <inertial pos="-0.06977 0.04479 0.00057" quat="0.595024 0.579772 0.394141 0.393019" mass="1.469" diaginertia="0.00252289 0.00208104 0.00139163"/>
        <joint name="abad_L_Joint" pos="0 0 0" axis="1 0 0" limited="true" range="-0.38397 1.39626"/>
        <geom class="visual" rgba="0.79216 0.81961 0.93333 1" mesh="abad_L_Link"/>
        <geom name="abad_L_collision" type="mesh" mesh="abad_L_Link" rgba="0 0 1 0"/>

        <body name="hip_L_Link" pos="-0.077 0.0205 0">
          <inertial pos="-0.02869 -0.0477 -0.03992" quat="0.853885 0.192797 0.226903 0.426877" mass="2.3" diaginertia="0.0233264 0.0230229 0.00277548"/>
          <joint name="hip_L_Joint" pos="0 0 0" axis="0 1 0" limited="true" range="-1.01229 1.39626"/>
          <geom class="visual" rgba="1 1 1 1" mesh="hip_L_Link"/>
          <geom name="hip_L_collision" type="mesh" mesh="hip_L_Link" rgba="0 0 1 0"/>

          <body name="knee_L_Link" pos="-0.15 -0.0205 -0.25981">
            <inertial pos="0.11913 0.01106 -0.20363" quat="0.687012 -0.159981 -0.201582 0.679548" mass="1.49" diaginertia="0.0177107 0.0171855 0.001015"/>
            <joint name="knee_L_Joint" pos="0 0 0" axis="0 -1 0" limited="true" range="-0.872665 1.36136"/>
            <geom class="visual" rgba="0.79216 0.81961 0.93333 1" mesh="knee_L_Link"/>
            <geom name="knee_L_collision" type="mesh" mesh="knee_L_Link" rgba="0 0 1 0"/>

            <body name="wheel_L_Link" pos="0.15 0.0435 -0.25981">
              <inertial pos="3e-05 0.00807 -2e-05" quat="0.683013 0.183016 0.183017 0.683011" mass="1.08" diaginertia="0.00974272 0.00515568 0.00515344"/>
              <joint name="wheel_L_Joint" pos="0 0 0" axis="0 1 0" limited="true" range="-1000000 1000000" frictionloss="0.01"/>
              <geom class="visual" rgba="0.26667 0.26667 0.26667 1" mesh="wheel_L_Link"/>
              <geom name="L_foot" type="mesh" mesh="wheel_L_Link" rgba="1 0.423529 0.0392157 1"/>
              <site name="L" pos="0 0.008 0" type="sphere" size="0.02" group="5"/>
            </body>
          </body>
        </body>
      </body>

      <body name="abad_R_Link" pos="0.05556 -0.105 -0.2602">
        <inertial pos="-0.06977 -0.04479 0.00057" quat="0.393019 0.394141 0.579772 0.595024" mass="1.469" diaginertia="0.00252289 0.00208104 0.00139163"/>
        <joint name="abad_R_Joint" pos="0 0 0" axis="1 0 0" limited="true" range="-1.39626 0.38397"/>
        <geom class="visual" rgba="0.79216 0.81961 0.93333 1" mesh="abad_R_Link"/>
        <geom name="abad_R_collision" type="mesh" mesh="abad_R_Link" rgba="0 0 1 0"/>

        <body name="hip_R_Link" pos="-0.077 -0.0205 0">
          <inertial pos="-0.02869 0.0477 -0.03992" quat="0.426877 0.226903 0.192797 0.853885" mass="2.3" diaginertia="0.0233264 0.0230229 0.00277548"/>
          <joint name="hip_R_Joint" pos="0 0 0" axis="0 -1 0" limited="true" range="-1.39626 1.01229"/>
          <geom class="visual" rgba="1 1 1 1" mesh="hip_R_Link"/>
          <geom name="hip_R_collision" type="mesh" mesh="hip_R_Link" rgba="0 0 1 0"/>

          <body name="knee_R_Link" pos="-0.15 0.0205 -0.25981">
            <inertial pos="0.11913 -0.01106 -0.20363" quat="0.679548 -0.201582 -0.159981 0.687012" mass="1.49" diaginertia="0.0177107 0.0171855 0.001015"/>
            <joint name="knee_R_Joint" pos="0 0 0" axis="0 1 0" limited="true" range="-1.36136 0.872665"/>
            <geom class="visual" rgba="0.79216 0.81961 0.93333 1" mesh="knee_R_Link"/>
            <geom name="knee_R_collision" type="mesh" mesh="knee_R_Link" rgba="0 0 1 0"/>

            <body name="wheel_R_Link" pos="0.15 -0.0435 -0.25981">
              <inertial pos="3e-05 -0.00807 -2e-05" quat="0.683011 0.183017 0.183016 0.683013" mass="1.08" diaginertia="0.00974272 0.00515568 0.00515344"/>
              <joint name="wheel_R_Joint" pos="0 0 0" axis="0 1 0" limited="true" range="-1000000 1000000" frictionloss="0.01"/>
              <geom class="visual" rgba="0.26667 0.26667 0.26667 1" mesh="wheel_R_Link"/>
              <geom name="R_foot" type="mesh" mesh="wheel_R_Link" rgba="1 0.423529 0.0392157 1"/>
              <site name="R" pos="0 -0.008 0" type="sphere" size="0.02" group="5"/>
            </body>
          </body>
        </body>
      </body>
    </body>
  </worldbody>

  <contact>
    <exclude body1="base" body2="hip_L_Link"/>
    <exclude body1="base" body2="hip_R_Link"/>
  </contact>

  <sensor>
    <gyro name="imu_ang_vel" site="imu"/>
    <velocimeter name="imu_lin_vel" site="imu"/>
    <accelerometer name="imu_lin_acc" site="imu"/>
    <subtreeangmom name="root_angmom" body="base"/>
  </sensor>
</mujoco>
